[2025-05-13 16:17:59 +0000] [7591] [INFO] Handling signal: winch
[2025-05-13 16:17:59 +0000] [7591] [INFO] Handling signal: winch
[2025-05-13 16:17:59 +0000] [7591] [INFO] Handling signal: winch
[2025-05-13 16:17:59 +0000] [7591] [INFO] Handling signal: winch
2025-05-13 16:17:59,826 - core.mitre_parser - INFO - Loaded MITRE ATT&CK data from local cache: /home/runner/workspace/mitre/attack.json
2025-05-13 16:17:59,848 - core.mitre_parser - INFO - Parsed 14 tactics and 823 techniques
2025-05-13 16:17:59,915 - core.mitre_parser - INFO - Loaded MITRE ATT&CK data from local cache: /home/runner/workspace/mitre/attack.json
2025-05-13 16:17:59,926 - core.mitre_parser - INFO - Parsed 14 tactics and 823 techniques
[2025-05-13 16:18:00 +0000] [7591] [INFO] Handling signal: winch
2025-05-13 16:18:00,113 - core.mitre_parser - INFO - Loaded MITRE ATT&CK data from local cache: /home/runner/workspace/mitre/attack.json
2025-05-13 16:18:00,122 - core.mitre_parser - INFO - Parsed 14 tactics and 823 techniques
[2025-05-13 16:18:00 +0000] [7591] [INFO] Handling signal: winch
[2025-05-13 16:18:00 +0000] [7591] [INFO] Handling signal: winch
[2025-05-13 16:18:00 +0000] [7591] [INFO] Handling signal: winch
[2025-05-13 16:18:00 +0000] [7591] [INFO] Handling signal: winch
2025-05-13 16:18:00,617 - core.mitre_parser - INFO - Loaded MITRE ATT&CK data from local cache: /home/runner/workspace/mitre/attack.json
2025-05-13 16:18:00,624 - core.mitre_parser - INFO - Parsed 14 tactics and 823 techniques
2025-05-13 16:18:36,843 - core.sigma_loader - INFO - Loaded 2794 Sigma rules from 2794 files
2025-05-13 16:18:36,843 - core.field_mapper - INFO - Loaded field mappings from /home/runner/workspace/mappings/fieldmap.json
2025-05-13 16:18:36,944 - core.sigma_loader - INFO - Loaded 2794 Sigma rules from 2794 files
2025-05-13 16:18:36,944 - core.field_mapper - INFO - Loaded field mappings from /home/runner/workspace/mappings/fieldmap.json
2025-05-13 16:18:37,521 - core.ai_assistant - WARNING - OPENAI_API_KEY environment variable not set
2025-05-13 16:18:37,521 - core.splunk_query - INFO - Attempting to connect to Splunk at 192.168.244.128:8089 with scheme http...
2025-05-13 16:18:37,622 - core.ai_assistant - WARNING - OPENAI_API_KEY environment variable not set
2025-05-13 16:18:37,624 - core.splunk_query - INFO - Attempting to connect to Splunk at 192.168.244.128:8089 with scheme http...
2025-05-13 16:18:37,667 - core.sigma_loader - INFO - Loaded 2794 Sigma rules from 2794 files
2025-05-13 16:18:37,667 - core.field_mapper - INFO - Loaded field mappings from /home/runner/workspace/mappings/fieldmap.json
2025-05-13 16:18:37,737 - core.sigma_loader - INFO - Loaded 2794 Sigma rules from 2794 files
2025-05-13 16:18:37,737 - core.field_mapper - INFO - Loaded field mappings from /home/runner/workspace/mappings/fieldmap.json
2025-05-13 16:18:37,937 - core.ai_assistant - WARNING - OPENAI_API_KEY environment variable not set
2025-05-13 16:18:37,937 - core.splunk_query - INFO - Attempting to connect to Splunk at 192.168.244.128:8089 with scheme http...
2025-05-13 16:18:37,996 - core.ai_assistant - WARNING - OPENAI_API_KEY environment variable not set
2025-05-13 16:18:37,996 - core.splunk_query - INFO - Attempting to connect to Splunk at 192.168.244.128:8089 with scheme http...
2025-05-13 16:18:47,532 - core.splunk_query - ERROR - Connection to Splunk timed out after 10 seconds
2025-05-13 16:18:47,532 - app - WARNING - Failed to connect to Splunk on startup
[2025-05-13 16:18:47 +0000] [7602] [ERROR] Exception in worker process
Traceback (most recent call last):
  File "/home/runner/workspace/.pythonlibs/lib/python3.11/site-packages/gunicorn/arbiter.py", line 608, in spawn_worker
    worker.init_process()
  File "/home/runner/workspace/.pythonlibs/lib/python3.11/site-packages/gunicorn/workers/base.py", line 135, in init_process
    self.load_wsgi()
  File "/home/runner/workspace/.pythonlibs/lib/python3.11/site-packages/gunicorn/workers/base.py", line 147, in load_wsgi
    self.wsgi = self.app.wsgi()
                ^^^^^^^^^^^^^^^
  File "/home/runner/workspace/.pythonlibs/lib/python3.11/site-packages/gunicorn/app/base.py", line 66, in wsgi
    self.callable = self.load()
                    ^^^^^^^^^^^
  File "/home/runner/workspace/.pythonlibs/lib/python3.11/site-packages/gunicorn/app/wsgiapp.py", line 57, in load
    return self.load_wsgiapp()
           ^^^^^^^^^^^^^^^^^^^
  File "/home/runner/workspace/.pythonlibs/lib/python3.11/site-packages/gunicorn/app/wsgiapp.py", line 47, in load_wsgiapp
    return util.import_app(self.app_uri)
           ^^^^^^^^^^^^^^^^^^^^^^^^^^^^^
  File "/home/runner/workspace/.pythonlibs/lib/python3.11/site-packages/gunicorn/util.py", line 370, in import_app
    mod = importlib.import_module(module)
          ^^^^^^^^^^^^^^^^^^^^^^^^^^^^^^^
  File "/nix/store/clx0mcir7qw8zk36zbr4jra789g3knf6-python3-3.11.10/lib/python3.11/importlib/__init__.py", line 126, in import_module
    return _bootstrap._gcd_import(name[level:], package, level)
           ^^^^^^^^^^^^^^^^^^^^^^^^^^^^^^^^^^^^^^^^^^^^^^^^^^^^
  File "<frozen importlib._bootstrap>", line 1204, in _gcd_import
  File "<frozen importlib._bootstrap>", line 1176, in _find_and_load
  File "<frozen importlib._bootstrap>", line 1147, in _find_and_load_unlocked
  File "<frozen importlib._bootstrap>", line 690, in _load_unlocked
  File "<frozen importlib._bootstrap_external>", line 940, in exec_module
  File "<frozen importlib._bootstrap>", line 241, in _call_with_frames_removed
  File "/home/runner/workspace/app.py", line 59, in <module>
    import routes
  File "/home/runner/workspace/routes.py", line 7, in <module>
    from threading import Thread, current_app
ImportError: cannot import name 'current_app' from 'threading' (/nix/store/clx0mcir7qw8zk36zbr4jra789g3knf6-python3-3.11.10/lib/python3.11/threading.py)
[2025-05-13 16:18:47 +0000] [7602] [INFO] Worker exiting (pid: 7602)
2025-05-13 16:18:47,636 - core.splunk_query - ERROR - Connection to Splunk timed out after 10 seconds
2025-05-13 16:18:47,636 - app - WARNING - Failed to connect to Splunk on startup
[2025-05-13 16:18:47 +0000] [7603] [ERROR] Exception in worker process
Traceback (most recent call last):
  File "/home/runner/workspace/.pythonlibs/lib/python3.11/site-packages/gunicorn/arbiter.py", line 608, in spawn_worker
    worker.init_process()
  File "/home/runner/workspace/.pythonlibs/lib/python3.11/site-packages/gunicorn/workers/base.py", line 135, in init_process
    self.load_wsgi()
  File "/home/runner/workspace/.pythonlibs/lib/python3.11/site-packages/gunicorn/workers/base.py", line 147, in load_wsgi
    self.wsgi = self.app.wsgi()
                ^^^^^^^^^^^^^^^
  File "/home/runner/workspace/.pythonlibs/lib/python3.11/site-packages/gunicorn/app/base.py", line 66, in wsgi
    self.callable = self.load()
                    ^^^^^^^^^^^
  File "/home/runner/workspace/.pythonlibs/lib/python3.11/site-packages/gunicorn/app/wsgiapp.py", line 57, in load
    return self.load_wsgiapp()
           ^^^^^^^^^^^^^^^^^^^
  File "/home/runner/workspace/.pythonlibs/lib/python3.11/site-packages/gunicorn/app/wsgiapp.py", line 47, in load_wsgiapp
    return util.import_app(self.app_uri)
           ^^^^^^^^^^^^^^^^^^^^^^^^^^^^^
  File "/home/runner/workspace/.pythonlibs/lib/python3.11/site-packages/gunicorn/util.py", line 370, in import_app
    mod = importlib.import_module(module)
          ^^^^^^^^^^^^^^^^^^^^^^^^^^^^^^^
  File "/nix/store/clx0mcir7qw8zk36zbr4jra789g3knf6-python3-3.11.10/lib/python3.11/importlib/__init__.py", line 126, in import_module
    return _bootstrap._gcd_import(name[level:], package, level)
           ^^^^^^^^^^^^^^^^^^^^^^^^^^^^^^^^^^^^^^^^^^^^^^^^^^^^
  File "<frozen importlib._bootstrap>", line 1204, in _gcd_import
  File "<frozen importlib._bootstrap>", line 1176, in _find_and_load
  File "<frozen importlib._bootstrap>", line 1147, in _find_and_load_unlocked
  File "<frozen importlib._bootstrap>", line 690, in _load_unlocked
  File "<frozen importlib._bootstrap_external>", line 940, in exec_module
  File "<frozen importlib._bootstrap>", line 241, in _call_with_frames_removed
  File "/home/runner/workspace/app.py", line 59, in <module>
    import routes
  File "/home/runner/workspace/routes.py", line 7, in <module>
    from threading import Thread, current_app
ImportError: cannot import name 'current_app' from 'threading' (/nix/store/clx0mcir7qw8zk36zbr4jra789g3knf6-python3-3.11.10/lib/python3.11/threading.py)
[2025-05-13 16:18:47 +0000] [7603] [INFO] Worker exiting (pid: 7603)
2025-05-13 16:18:47,948 - core.splunk_query - ERROR - Connection to Splunk timed out after 10 seconds
2025-05-13 16:18:47,948 - app - WARNING - Failed to connect to Splunk on startup
[2025-05-13 16:18:47 +0000] [7604] [ERROR] Exception in worker process
Traceback (most recent call last):
  File "/home/runner/workspace/.pythonlibs/lib/python3.11/site-packages/gunicorn/arbiter.py", line 608, in spawn_worker
    worker.init_process()
  File "/home/runner/workspace/.pythonlibs/lib/python3.11/site-packages/gunicorn/workers/base.py", line 135, in init_process
    self.load_wsgi()
  File "/home/runner/workspace/.pythonlibs/lib/python3.11/site-packages/gunicorn/workers/base.py", line 147, in load_wsgi
    self.wsgi = self.app.wsgi()
                ^^^^^^^^^^^^^^^
  File "/home/runner/workspace/.pythonlibs/lib/python3.11/site-packages/gunicorn/app/base.py", line 66, in wsgi
    self.callable = self.load()
                    ^^^^^^^^^^^
  File "/home/runner/workspace/.pythonlibs/lib/python3.11/site-packages/gunicorn/app/wsgiapp.py", line 57, in load
    return self.load_wsgiapp()
           ^^^^^^^^^^^^^^^^^^^
  File "/home/runner/workspace/.pythonlibs/lib/python3.11/site-packages/gunicorn/app/wsgiapp.py", line 47, in load_wsgiapp
    return util.import_app(self.app_uri)
           ^^^^^^^^^^^^^^^^^^^^^^^^^^^^^
  File "/home/runner/workspace/.pythonlibs/lib/python3.11/site-packages/gunicorn/util.py", line 370, in import_app
    mod = importlib.import_module(module)
          ^^^^^^^^^^^^^^^^^^^^^^^^^^^^^^^
  File "/nix/store/clx0mcir7qw8zk36zbr4jra789g3knf6-python3-3.11.10/lib/python3.11/importlib/__init__.py", line 126, in import_module
    return _bootstrap._gcd_import(name[level:], package, level)
           ^^^^^^^^^^^^^^^^^^^^^^^^^^^^^^^^^^^^^^^^^^^^^^^^^^^^
  File "<frozen importlib._bootstrap>", line 1204, in _gcd_import
  File "<frozen importlib._bootstrap>", line 1176, in _find_and_load
  File "<frozen importlib._bootstrap>", line 1147, in _find_and_load_unlocked
  File "<frozen importlib._bootstrap>", line 690, in _load_unlocked
  File "<frozen importlib._bootstrap_external>", line 940, in exec_module
  File "<frozen importlib._bootstrap>", line 241, in _call_with_frames_removed
  File "/home/runner/workspace/app.py", line 59, in <module>
    import routes
  File "/home/runner/workspace/routes.py", line 7, in <module>
    from threading import Thread, current_app
ImportError: cannot import name 'current_app' from 'threading' (/nix/store/clx0mcir7qw8zk36zbr4jra789g3knf6-python3-3.11.10/lib/python3.11/threading.py)
[2025-05-13 16:18:47 +0000] [7604] [INFO] Worker exiting (pid: 7604)
2025-05-13 16:18:48,010 - core.splunk_query - ERROR - Connection to Splunk timed out after 10 seconds
2025-05-13 16:18:48,010 - app - WARNING - Failed to connect to Splunk on startup
[2025-05-13 16:18:48 +0000] [7605] [ERROR] Exception in worker process
Traceback (most recent call last):
  File "/home/runner/workspace/.pythonlibs/lib/python3.11/site-packages/gunicorn/arbiter.py", line 608, in spawn_worker
    worker.init_process()
  File "/home/runner/workspace/.pythonlibs/lib/python3.11/site-packages/gunicorn/workers/base.py", line 135, in init_process
    self.load_wsgi()
  File "/home/runner/workspace/.pythonlibs/lib/python3.11/site-packages/gunicorn/workers/base.py", line 147, in load_wsgi
    self.wsgi = self.app.wsgi()
                ^^^^^^^^^^^^^^^
  File "/home/runner/workspace/.pythonlibs/lib/python3.11/site-packages/gunicorn/app/base.py", line 66, in wsgi
    self.callable = self.load()
                    ^^^^^^^^^^^
  File "/home/runner/workspace/.pythonlibs/lib/python3.11/site-packages/gunicorn/app/wsgiapp.py", line 57, in load
    return self.load_wsgiapp()
           ^^^^^^^^^^^^^^^^^^^
  File "/home/runner/workspace/.pythonlibs/lib/python3.11/site-packages/gunicorn/app/wsgiapp.py", line 47, in load_wsgiapp
    return util.import_app(self.app_uri)
           ^^^^^^^^^^^^^^^^^^^^^^^^^^^^^
  File "/home/runner/workspace/.pythonlibs/lib/python3.11/site-packages/gunicorn/util.py", line 370, in import_app
    mod = importlib.import_module(module)
          ^^^^^^^^^^^^^^^^^^^^^^^^^^^^^^^
  File "/nix/store/clx0mcir7qw8zk36zbr4jra789g3knf6-python3-3.11.10/lib/python3.11/importlib/__init__.py", line 126, in import_module
    return _bootstrap._gcd_import(name[level:], package, level)
           ^^^^^^^^^^^^^^^^^^^^^^^^^^^^^^^^^^^^^^^^^^^^^^^^^^^^
  File "<frozen importlib._bootstrap>", line 1204, in _gcd_import
  File "<frozen importlib._bootstrap>", line 1176, in _find_and_load
  File "<frozen importlib._bootstrap>", line 1147, in _find_and_load_unlocked
  File "<frozen importlib._bootstrap>", line 690, in _load_unlocked
  File "<frozen importlib._bootstrap_external>", line 940, in exec_module
  File "<frozen importlib._bootstrap>", line 241, in _call_with_frames_removed
  File "/home/runner/workspace/app.py", line 59, in <module>
    import routes
  File "/home/runner/workspace/routes.py", line 7, in <module>
    from threading import Thread, current_app
ImportError: cannot import name 'current_app' from 'threading' (/nix/store/clx0mcir7qw8zk36zbr4jra789g3knf6-python3-3.11.10/lib/python3.11/threading.py)
[2025-05-13 16:18:48 +0000] [7605] [INFO] Worker exiting (pid: 7605)
[2025-05-13 16:18:48 +0000] [7591] [ERROR] Worker (pid:7602) exited with code 3
[2025-05-13 16:18:48 +0000] [7591] [ERROR] Worker (pid:7604) was sent SIGTERM!
[2025-05-13 16:18:48 +0000] [7591] [ERROR] Worker (pid:7605) was sent SIGTERM!
[2025-05-13 16:18:48 +0000] [7591] [ERROR] Worker (pid:7603) was sent SIGTERM!
[2025-05-13 16:18:48 +0000] [7591] [ERROR] Shutting down: Master
[2025-05-13 16:18:48 +0000] [7591] [ERROR] Reason: Worker failed to boot.
